Workbook

Sheet AGT-1
A1: TGL | C1: KETERANGAN | D1: MASUK | E1: KELUAR | F1: SALDO
A2: 2025 | C2: LIST SETORAN TUNAI DAN TRANSFER SELAMA PEMBANGUNAN :
A3: AGUSTUS | B3: 5 | C3: Transfer Biaya AJB Tanah di Jonggol | D3: 40000000
B4: 10 | C4: DP Biaya Pembangunan Kandang KEVIN yang PERTAMA | D4: 200000000
C5: TOTAL TRANSFER & SETORAN TUNAI PEMBANGUNAN KANDANG KEVIN | F5: =SUM(D3:D4) -> 240000000
C7: LIST PEMBELIAN DAN PEMBANGUNAN KANDANG :
A8: AGUSTUS | B8: 10 | C8: Pembayaran biaya AJB Tanah di Jonggol | E8: 40000000 | F8: =F5+D8-E8 -> 200000000
B9: 10 | C9: Pembayaran biaya perijinan lingkungan | E9: 10000000 | F9: =F8+D9-E9 -> 190000000
B10: 11 | C10: Tambahan Biaya Ijin Lingkungan (Tambahan ke penduduk sekitar) | E10: 3000000 | F10: =F9+D10-E10 -> 187000000
B11: 16 | C11: Pembelian kopi & air untuk tukang buka lahan | E11: 250000 | F11: =F10+D11-E11 -> 186750000
B12: 16 | C12: Pemberian upah tukang untuk buka lahan | E12: 500000 | F12: =F11+D12-E12 -> 186250000
B13: 16 | C13: Pembayaran pembelian material (BON 01#) : | F13: =F12+D13-E13 -> 186250000
C14: # 33 Kayu 10x10 @50.000 | E14: =33*50000 -> 1650000 | F14: =F13+D14-E14 -> 184600000 | H14: =SUM(E14:E48) -> 29771000
C15: # 117 Kayu 5x10 @23.000 | E15: =117*23000 -> 2691000 | F15: =F14+D15-E15 -> 181909000
C16: # 43 Kayu 6x12 @60.000 | E16: =43*60000 -> 2580000 | F16: =F15+D16-E16 -> 179329000
B17: 16 | C17: Pembayaran pembelian material (BON 02#) : | F17: =F16+D17-E17 -> 179329000
C18: # 2 mobil pasir @350.000 | E18: =2*350000 -> 700000 | F18: =F17+D18-E18 -> 178629000
C19: # 10 mobil batu @320.000 | E19: =10*320000 -> 3200000 | F19: =F18+D19-E19 -> 175429000
B20: 16 | C20: Pembayaran pembelian material (BON 03#) : | F20: =F19+D20-E20 -> 175429000
C21: # 150 bambu @15.000 | E21: =150*15000 -> 2250000 | F21: =F20+D21-E21 -> 173179000
B22: 16 | C22: Pembayaran tukang dalam pembangunan kandang @150.000 (PEKAN #1) : | F22: =F21+D22-E22 -> 173179000
C23: # Miyah 5,5 hari | E23: =5.5*150000 -> 825000 | F23: =F22+D23-E23 -> 172354000
C24: # RT 1 hari | E24: =1*150000 -> 150000 | F24: =F23+D24-E24 -> 172204000
C25: # Eka 5,5 hari | E25: =5.5*150000 -> 825000 | F25: =F24+D25-E25 -> 171379000
C26: # Eti 1 hari | E26: =1*150000 -> 150000 | F26: =F25+D26-E26 -> 171229000
C27: # Oyib 5,5 hari | E27: =5.5*150000 -> 825000 | F27: =F26+D27-E27 -> 170404000
C28: # Ansar 5,5 hari | E28: =5.5*150000 -> 825000 | F28: =F27+D28-E28 -> 169579000
C29: # Iding 4,5 hari | E29: =4.5*150000 -> 675000 | F29: =F28+D29-E29 -> 168904000
C30: # Ajo 5,5 hari | E30: =5.5*150000 -> 825000 | F30: =F29+D30-E30 -> 168079000
C31: # Edi 5,5 hari | E31: =5.5*150000 -> 825000 | F31: =F30+D31-E31 -> 167254000
C32: # Beni 4,5 hari | E32: =4.5*150000 -> 675000 | F32: =F31+D32-E32 -> 166579000
C33: # Bodong 4,5 hari | E33: =4.5*150000 -> 675000 | F33: =F32+D33-E33 -> 165904000
C34: # Abluk 2,5 hari | E34: =2.5*150000 -> 375000 | F34: =F33+D34-E34 -> 165529000
C35: # Ubung 1 hari | E35: =1*150000 -> 150000 | F35: =F34+D35-E35 -> 165379000
B36: 16 | C36: Pembayaran pembelian material (BON 04#) : | F36: =F35+D36-E36 -> 165379000
C37: # 3 mobil pasir @350.000 | E37: =3*350000 -> 1050000 | F37: =F36+D37-E37 -> 164329000
C38: # 10 semen 50 kg @56.000 | E38: =10*56000 -> 560000 | F38: =F37+D38-E38 -> 163769000
C39: # 35 besi 3/8 @55.000 | E39: =35*55000 -> 1925000 | F39: =F38+D39-E39 -> 161844000
C40: # 60 hong 30 @75.000 | E40: =60*75000 -> 4500000 | F40: =F39+D40-E40 -> 157344000
C41: # 1 roda troli @550.000 | E41: =550000 -> 550000 | F41: =F40+D41-E41 -> 156794000
...

Sheet SEP-1
A1: TGL | C1: KETERANGAN | D1: MASUK | E1: KELUAR | F1: SALDO
A2: 2025 | C2: LIST SETORAN TUNAI DAN TRANSFER SELAMA PEMBANGUNAN :
A3: SEPTEMBER | B3: 11 | C3: DP Biaya Pembangunan Kandang KEVIN yang KEDUA | D3: 100000000
C4: TOTAL TRANSFER & SETORAN TUNAI PEMBANGUNAN KANDANG KEVIN | F4: =SUM(D3:D3) -> 100000000
C6: LIST PEMBELIAN DAN PEMBANGUNAN KANDANG :
A7: SEPTEMBER | C7: SALDO SEBELUMNYA | D7: ='AGT-1'!D138 -> 240000000 | E7: ='AGT-1'!E138 -> 152672500 | F7: ='AGT-1'!F138 -> 87327500
B8: 3 | C8: Pembayaran pembelian material (BON 19#) : | F8: =F4+F7+D8-E8 -> 187327500
C9: # 131 Kayu 5x10 @23.000 | E9: =131*23000 -> 3013000 | F9: =F8+D9-E9 -> 184314500
C10: # 54 Kayu 2x20 @23.000 | E10: =54*23000 -> 1242000 | F10: =F9+D10-E10 -> 183072500
B11: 5 | C11: Pembayaran pembelian material (BON 20#) : | F11: =F10+D11-E11 -> 183072500
C12: # 3 mobil pasir @350.000 | E12: =3*350000 -> 1050000 | F12: =F11+D12-E12 -> 182022500 | H12: =SUM(E12:E45) -> 34695000
C13: # 2 Kikir @30.000 | E13: =2*30000 -> 60000 | F13: =F12+D13-E13 -> 181962500
C14: # 150 Asbes 3m @80.000 | E14: =150*80000 -> 12000000 | F14: =F13+D14-E14 -> 169962500 | H14: =SUM(E12:E20) -> 21070000
C15: # 65 Asbes 240 @68.000 | E15: =65*68000 -> 4420000 | F15: =F14+D15-E15 -> 165542500 | H15: =SUM(E22:E33) -> 5575000
C16: # 27 Nok asbes @40.000 | E16: =27*40000 -> 1080000 | F16: =F15+D16-E16 -> 164462500 | H16: =SUM(E35:E45) -> 8050000
C17: # 3kg Paku asbes @30.000 | E17: =3*30000 -> 90000 | F17: =F16+D17-E17 -> 164372500
C18: # 1 Karet asbes @30.000 | E18: =30000 -> 30000 | F18: =F17+D18-E18 -> 164342500 | H18: =SUM(H14:H16) -> 34695000
C19: # 15 Semen @56.000 | E19: =15*56000 -> 840000 | F19: =F18+D19-E19 -> 163502500
C20: # 20 Hong @75.000 | E20: =20*75000 -> 1500000 | F20: =F19+D20-E20 -> 162002500
B21: 5 | C21: Pembayaran pembelian material (BON 21#) : | F21: =F20+D21-E21 -> 162002500
C22: # 20 Semen @56.000 | E22: =20*56000 -> 1120000 | F22: =F21+D22-E22 -> 160882500
C23: # 25kg Paku 5 @20.000 | E23: =25*20000 -> 500000 | F23: =F22+D23-E23 -> 160382500 | H23: =SUM(E8:E45) -> 38950000
C24: # 6 Keni 3/4 @4.000 | E24: =6*4000 -> 24000 | F24: =F23+D24-E24 -> 160358500
C25: # 1 Sok derat dalem @5.000 | E25: =5000 -> 5000 | F25: =F24+D25-E25 -> 160353500 | H25: 23324000
C26: # 1 Bola Pelampung @95.000 | E26: =95000 -> 95000 | F26: =F25+D26-E26 -> 160258500
C27: # 2 Plosok 3/4 - 1/2 @5.000 | E27: =2*5000 -> 10000 | F27: =F26+D27-E27 -> 160248500
C28: # 2 Siltip @3.000 | E28: =2*3000 -> 6000 | F28: =F27+D28-E28 -> 160242500
C29: # 5 mobil pasir @350.000 | E29: =5*350000 -> 1750000 | F29: =F28+D29-E29 -> 158492500
C30: # 3 Pensil @5.000 | E30: =3*5000 -> 15000 | F30: =F29+D30-E30 -> 158477500
C31: # 1 pak Sarung tangan @50.000 | E31: =50000 -> 50000 | F31: =F30+D31-E31 -> 158427500
C32: # 1 dus Paku 10 @500.000 | E32: =500000 -> 500000 | F32: =F31+D32-E32 -> 157927500
C33: # 20 Hong 30 @75.000 | E33: =20*75000 -> 1500000 | F33: =F32+D33-E33 -> 156427500
B34: 5 | C34: Pembayaran pembelian material (BON 22#) : | F34: =F33+D34-E34 -> 156427500
C35: # 10 Hong 30 @75.000 | E35: =10*75000 -> 750000 | F35: =F34+D35-E35 -> 155677500
C36: # 10kg Paku 10 @20.000 | E36: =10*20000 -> 200000 | F36: =F35+D36-E36 -> 155477500
C37: # 10kg Paku 7 @20.000 | E37: =10*20000 -> 200000 | F37: =F36+D37-E37 -> 155277500
C38: # 1 set Gergaji besi @45.000 | E38: =45000 -> 45000 | F38: =F37+D38-E38 -> 155232500
C39: # 1 Palu @35.000 | E39: =35000 -> 35000 | F39: =F38+D39-E39 -> 155197500
C40: # 45 Besi 3/8 @55.000 | E40: =45*55000 -> 2475000 | F40: =F39+D40-E40 -> 152722500
C41: # 10 Semen @56.000 | E41: =10*56000 -> 560000 | F41: =F40+D41-E41 -> 152162500
...

Sheet OKT-1
A1: TGL | C1: KETERANGAN | D1: MASUK | E1: KELUAR | F1: SALDO
A2: 2025 | C2: LIST SETORAN TUNAI DAN TRANSFER SELAMA PEMBANGUNAN :
A3: OKTOBER | B3: 7 | C3: DP Biaya Pembangunan Mess dan Gudang KEVIN | D3: 100000000
B4: 25 | C4: DP Biaya Pembangunan Mess dan Gudang KEVIN | D4: 50000000
C5: TOTAL TRANSFER & SETORAN TUNAI PEMBANGUNAN KANDANG KEVIN | F5: =SUM(D3:D4) -> 150000000
C7: LIST PEMBELIAN DAN PEMBANGUNAN KANDANG :
A8: OKTOBER | C8: SALDO SEBELUMNYA | D8: ='SEP-1'!D243 -> 340000000 | E8: ='SEP-1'!E243 -> 339478500 | F8: ='SEP-1'!F243 -> 521500
B9: 1 | C9: Pembayaran pembelian material (BON 44#) : | F9: =F5+F8+D9-E9 -> 150521500
C10: # 100 Kayu 5x10 @23.000 | E10: =100*23000 -> 2300000 | F10: =F9+D10-E10 -> 148221500
B11: 2 | C11: Pembayaran pembelian material (BON 45#) : | F11: =F10+D11-E11 -> 148221500
C12: # 150 Kayu 4x6 @23.000 | E12: =150*23000 -> 3450000 | F12: =F11+D12-E12 -> 144771500
B13: 3 | C13: Pembayaran pembelian material (BON 46#) : | F13: =F12+D13-E13 -> 144771500
C14: # 7 mobil batu @320.000 | E14: =7*320000 -> 2240000 | F14: =F13+D14-E14 -> 142531500
B15: 4 | C15: Pembayaran pembelian material (BON 47#) : | F15: =F14+D15-E15 -> 142531500
C16: # 1 engkel pasir | E16: 1800000 | F16: =F15+D16-E16 -> 140731500 | H16: =SUM(E10:E16) -> 9790000
B17: 4 | C17: Pembayaran tukang dalam pembangunan kandang @150.000 (PEKAN #8) : | F17: =F16+D17-E17 -> 140731500
C18: # Miyah 7 hari | E18: =7*150000 -> 1050000 | F18: =F17+D18-E18 -> 139681500
C19: # RT.02 7 hari | E19: =7*150000 -> 1050000 | F19: =F18+D19-E19 -> 138631500
C20: # Beni 7 hari | E20: =7*150000 -> 1050000 | F20: =F19+D20-E20 -> 137581500
C21: # Oyib 7 hari | E21: =7*150000 -> 1050000 | F21: =F20+D21-E21 -> 136531500
C22: # Iding 4 hari | E22: =4*150000 -> 600000 | F22: =F21+D22-E22 -> 135931500
C23: # Eka 7 hari | E23: =7*150000 -> 1050000 | F23: =F22+D23-E23 -> 134881500
C24: # Edi 7 hari | E24: =7*150000 -> 1050000 | F24: =F23+D24-E24 -> 133831500
C25: # Bodong 7 hari | E25: =7*150000 -> 1050000 | F25: =F24+D25-E25 -> 132781500
C26: # Ajo 7 hari | E26: =7*150000 -> 1050000 | F26: =F25+D26-E26 -> 131731500
C27: # Abluk 7 hari | E27: =7*150000 -> 1050000 | F27: =F26+D27-E27 -> 130681500
C28: # Asir 7 hari | E28: =7*150000 -> 1050000 | F28: =F27+D28-E28 -> 129631500
C29: # Anip 7 hari | E29: =7*150000 -> 1050000 | F29: =F28+D29-E29 -> 128581500
C30: # Ubung 6 hari | E30: =6*150000 -> 900000 | F30: =F29+D30-E30 -> 127681500
C31: # RT.01 7 hari | E31: =7*150000 -> 1050000 | F31: =F30+D31-E31 -> 126631500
C32: # Eti 7 hari | E32: =7*150000 -> 1050000 | F32: =F31+D32-E32 -> 125581500
C33: # Maneung 7 hari | E33: =7*150000 -> 1050000 | F33: =F32+D33-E33 -> 124531500 | H33: =SUM(E18:E33) -> 16200000
B34: 4 | C34: Rondap | E34: 210000 | F34: =F33+D34-E34 -> 124321500
B35: 4 | C35: Bon Awin sumur bor | E35: =2000000+1000000 -> 3000000 | F35: =F34+D35-E35 -> 121321500
B36: 4 | C36: Kopi & air | E36: =100000+70000+85000+100000 -> 355000 | F36: =F35+D36-E36 -> 120966500
B37: 4 | C37: Bersihkan pohon | E37: 350000 | F37: =F36+D37-E37 -> 120616500
B38: 4 | C38: Bongkar baterai | E38: 250000 | F38: =F37+D38-E38 -> 120366500
B39: 4 | C39: Bayar rakit baterai 337 set @5.000 | E39: =337*5000 -> 1685000 | F39: =F38+D39-E39 -> 118681500 | H39: =SUM(E34:E39) -> 5850000 | I39: =SUM(H16:H39) -> 31840000 | J39: 302000
B40: 4 | C40: Pelunasan pembayaran sumur bor 60 m @250.000 = 15.000.000 - DP 1.000.000 (20 sep) - DP 2.500.000 (23 sep) - DP 3.000.000 (4 okt) = 8.500.000 | E40: 8500000 | F40: =F39+D40-E40 -> 110181500 | I40: =I39-J39 -> 31538000
C41: TOTAL | D41: =SUM(D2:D40) -> 490000000 | E41: =SUM(E2:E40) -> 379818500 | F41: =D41-E41 -> 110181500
...

Sheet NOV-1
A1: TGL | C1: KETERANGAN | D1: MASUK | E1: KELUAR | F1: SALDO
A2: 2025 | C2: LIST SETORAN TUNAI DAN TRANSFER SELAMA PEMBANGUNAN :
A3: NOVEMBER | B3: 1 | C3: DP Biaya Pembangunan Mess dan Gudang KEVIN | D3: 6000000
C4: TOTAL TRANSFER & SETORAN TUNAI PEMBANGUNAN KANDANG KEVIN | F4: =SUM(D3:D3) -> 6000000
C6: LIST PEMBELIAN DAN PEMBANGUNAN KANDANG :
A7: NOVEMBER | C7: SALDO SEBELUMNYA | D7: ='OKT-1'!D240 -> 490000000 | E7: ='OKT-1'!E240 -> 484244500 | F7: =D7-E7 -> 5755500
F8: =F4+F7+D8-E8 -> 11755500
F9: =F5+F8+D9-E9 -> 11755500
C10: TOTAL | D10: =SUM(D2:D9) -> 496000000 | E10: =SUM(E2:E9) -> 484244500 | F10: =D10-E10 -> 11755500
A15: TGL | C15: KETERANGAN | D15: MASUK | E15: KELUAR | F15: SALDO
A16: 2025 | C16: SALDO SEBELUMNYA | D16: =D10 -> 496000000 | E16: =E10 -> 484244500 | F16: =F10 -> 11755500
F17: =F16+D17-E17 -> 11755500
F18: =F17+D18-E18 -> 11755500
F19: =F18+D19-E19 -> 11755500
F20: =F19+D20-E20 -> 11755500
F21: =F20+D21-E21 -> 11755500
F22: =F21+D22-E22 -> 11755500
F23: =F22+D23-E23 -> 11755500
F24: =F23+D24-E24 -> 11755500
F25: =F24+D25-E25 -> 11755500
F26: =F25+D26-E26 -> 11755500
F27: =F26+D27-E27 -> 11755500
F28: =F27+D28-E28 -> 11755500
... F76: =F75+D76-E76 -> 11755500
C77: SALDO DANA PEMBANGUNAN KANDANG KEVIN FARM | D77: =SUM(D16:D76) -> 496000000 | E77: =SUM(E16:E76) -> 484244500 | F77: =D77-E77 -> 11755500
